<?xml version="1.0" ?>
<!-- Generated using onshape-to-robot -->
<!-- Onshape https://cad.onshape.com/documents/653d84768203eef17fdafd62/w/ca2b8950acac85338a8e9098/e/fe580aaf98bff73fae543fc0 -->
<robot name="description">
  <!-- Link base_link -->
  <link name="base_link">
    <inertial>
      <origin xyz="0 0 0" rpy="0 0 0"/>
      <mass value="1e-09"/>
      <inertia ixx="1e-09" ixy="0" ixz="0" iyy="1e-09" iyz="0" izz="1e-09"/>
    </inertial>
  </link>
  <!-- Link base_link_chassis -->
  <link name="base_link_chassis">
    <inertial>
      <origin xyz="-0.0162216 -0.000717355 0.0566354" rpy="0 0 0"/>
      <mass value="0.859503"/>
      <inertia ixx="0.00426152" ixy="-3.6973e-05" ixz="0.000157471" iyy="0.00488469" iyz="3.69074e-05" izz="0.00473196"/>
    </inertial>
    <!-- Part base_link_chassis -->
    <visual>
      <origin xyz="-0.0102058 0 0.003" rpy="3.14159 -0 1.5708"/>
      <geometry>
        <mesh filename="file://$(find rossy)/description/assets/base_link_chassis.stl"/>
      </geometry>
      <material name="base_link_chassis_material">
        <color rgba="1 0.501961 0 1"/>
      </material>
    </visual>
    <collision>
      <origin xyz="-0.0102058 0 0.053" rpy="3.14159 -0 1.5708"/>
      <geometry>
        <box size="0.170 0.190 0.106"/>
      </geometry>
    </collision>
    <!-- Part motor -->
    <visual>
      <origin xyz="0.567337 0.115606 0.182641" rpy="1.5708 0 -1.57083"/>
      <geometry>
        <mesh filename="file://$(find rossy)/description/assets/motor.stl"/>
      </geometry>
      <material name="motor_material">
        <color rgba="0.8 0.8 0.8 1"/>
      </material>
    </visual>
    
    <!-- Part shell -->
    <visual>
      <origin xyz="-0.037706 -0.0850001 0.041" rpy="0 0 1.5708"/>
      <geometry>
        <mesh filename="file://$(find rossy)/description/assets/shell.stl"/>
      </geometry>
      <material name="shell_material">
        <color rgba="0.0980392 0.0980392 0.0980392 1"/>
      </material>
    </visual>
    
    <!-- Part lidar -->
    <!-- <visual>
      <origin xyz="-0.0307058 -0.00250012 0.1371" rpy="1.5708 -0 -3.14159"/>
      <geometry>
        <mesh filename="file://$(find rossy)/description/assets/lidar.stl"/>
      </geometry>
      <material name="lidar_material">
        <color rgba="0.109804 0.109804 0.109804 1"/>
      </material>
    </visual> -->
    <collision>
      <origin xyz="-0.0307058 -0.00250012 0.1371" rpy="0 0 0"/>
      <geometry>
        <cylinder radius="0.045" length="0.055"/> 
      </geometry>
    </collision>

    <!-- Part motor_2 -->
    <visual>
      <origin xyz="-0.687748 -0.115606 0.182641" rpy="1.5708 -0 1.57076"/>
      <geometry>
        <mesh filename="file://$(find rossy)/description/assets/motor.stl"/>
      </geometry>
      <material name="motor_2_material">
        <color rgba="0.8 0.8 0.8 1"/>
      </material>
    </visual>
    
    <!-- Part caster_wheel -->
    <visual>
      <origin xyz="0.0397942 0 -0.005" rpy="1.5708 -0 1.5708"/>
      <geometry>
        <mesh filename="file://$(find rossy)/description/assets/caster_wheel.stl"/>
      </geometry>
      <material name="caster_wheel_material">
        <color rgba="0.0980392 0.0980392 0.0980392 1"/>
      </material>
    </visual>
    <collision>
      <origin xyz="0.0397942 0 -0.012" rpy="0 0 0"/>
      <geometry>
        <cylinder radius="0.014" length="0.024"/>
      </geometry>
    </collision>

    <!-- Part cover -->
    <visual>
      <origin xyz="-0.010206 -1.23456e-07 0.038" rpy="-0 -0 -1.5708"/>
      <geometry>
        <mesh filename="file://$(find rossy)/description/assets/cover.stl"/>
      </geometry>
      <material name="cover_material">
        <color rgba="0.0980392 0.0980392 0.0980392 1"/>
      </material>
    </visual>
    
    <!-- Part camera_mount_base -->
    <visual>
      <origin xyz="0.062794 -1.23456e-07 0.041" rpy="1.5708 0 -1.5708"/>
      <geometry>
        <mesh filename="file://$(find rossy)/description/assets/camera_mount_base.stl"/>
      </geometry>
      <material name="camera_mount_base_material">
        <color rgba="0.301961 0.301961 0.301961 1"/>
      </material>
    </visual>
    
    <!-- Part logitech_c270 -->
    <visual>
      <origin xyz="0.100572 0.0072075 0.0814124" rpy="1.53589 0 1.5708"/>
      <geometry>
        <mesh filename="file://$(find rossy)/description/assets/logitech_c270.stl"/>
      </geometry>
      <material name="logitech_c270_material">
        <color rgba="0.34902 0.34902 0.34902 1"/>
      </material>
    </visual>
    <collision>
      <origin xyz="0.100572 0.0072075 0.0814124" rpy="1.53589 0 1.5708"/>
      <geometry>
        <mesh filename="file://$(find rossy)/description/assets/logitech_c270.stl"/>
      </geometry>
    </collision>

    <!-- Part attachment -->
    <visual>
      <origin xyz="0.0627324 -1.23456e-07 0.062159" rpy="2.12071 -0 -1.5708"/>
      <geometry>
        <mesh filename="file://$(find rossy)/description/assets/attachment.stl"/>
      </geometry>
      <material name="attachment_material">
        <color rgba="0.301961 0.301961 0.301961 1"/>
      </material>
    </visual>
    
    <!-- Part logitech_c270c -->
    <visual>
      <origin xyz="0.064203 -1.23456e-07 0.04925" rpy="1.5708 -0 1.5708"/>
      <geometry>
        <mesh filename="file://$(find rossy)/description/assets/logitech_c270c.stl"/>
      </geometry>
      <material name="logitech_c270c_material">
        <color rgba="0.34902 0.34902 0.34902 1"/>
      </material>
    </visual>
    
    <!-- Part logitech_c270b -->
    <visual>
      <origin xyz="0.0806752 -0.000750123 0.0793169" rpy="2.1293 -0 -1.5708"/>
      <geometry>
        <mesh filename="file://$(find rossy)/description/assets/logitech_c270b.stl"/>
      </geometry>
      <material name="logitech_c270b_material">
        <color rgba="0.294118 0.294118 0.294118 1"/>
      </material>
    </visual>
    
  </link>
  <!-- Link wheel -->
  <link name="wheel">
    <inertial>
      <origin xyz="9.22e-09 -4.58e-10 0.0184924" rpy="0 0 0"/>
      <mass value="0.0545006"/>
      <inertia ixx="1.88142e-05" ixy="2.09e-10" ixz="6e-12" iyy="1.88079e-05" iyz="-2e-12" izz="3.08203e-05"/>
    </inertial>
    <!-- Part rim -->
    <visual>
      <origin xyz="-0 -0 0.00575" rpy="0 1.5708 0"/>
      <geometry>
        <mesh filename="file://$(find rossy)/description/assets/rim.stl"/>
      </geometry>
      <material name="rim_material">
        <color rgba="1 1 1 1"/>
      </material>
    </visual>
    
    <!-- Part tire -->
    <visual>
      <origin xyz="0 -0 0.01825" rpy="-0 1.5708 0"/>
      <geometry>
        <mesh filename="file://$(find rossy)/description/assets/tire.stl"/>
      </geometry>
      <material name="tire_material">
        <color rgba="0.301961 0.301961 0.301961 1"/>
      </material>
    </visual>
    <collision>
      <origin xyz="0 -0 0.01825" rpy="-0 0 0"/>
      <geometry>
        <cylinder radius="0.03" length="0.025"/>
      </geometry>
    </collision>
    <!-- Part hex_nut -->
    <visual>
      <origin xyz="0 -0 0.018" rpy="-1.5708 0 -0"/>
      <geometry>
        <mesh filename="file://$(find rossy)/description/assets/hex_nut.stl"/>
      </geometry>
      <material name="hex_nut_material">
        <color rgba="1 0.870588 0.529412 1"/>
      </material>
    </visual>
    
  </link>
  <!-- Joint from base_link_chassis to wheel -->
  <joint name="left_wheel" type="continuous">
    <origin xyz="-0.0602058 0.086 0.0085" rpy="-1.5708 -1.5708 0"/>
    <parent link="base_link_chassis"/>
    <child link="wheel"/>
    <axis xyz="0 0 1"/>
    <limit effort="10" velocity="10"/>
  </joint>
  <!-- Link wheel_2 -->
  <link name="wheel_2">
    <inertial>
      <origin xyz="9.22e-09 4.58e-10 -0.0184924" rpy="0 0 0"/>
      <mass value="0.0545006"/>
      <inertia ixx="1.88142e-05" ixy="-2.09e-10" ixz="-6e-12" iyy="1.88079e-05" iyz="-2e-12" izz="3.08203e-05"/>
    </inertial>
    <!-- Part rim_2 -->
    <visual>
      <origin xyz="0 -0 -0.00575" rpy="3.14159 -1.5708 0"/>
      <geometry>
        <mesh filename="file://$(find rossy)/description/assets/rim.stl"/>
      </geometry>
      <material name="rim_2_material">
        <color rgba="1 1 1 1"/>
      </material>
    </visual>
    
    <!-- Part tire_2 -->
    <visual>
      <origin xyz="0 -0 -0.01825" rpy="3.14159 -1.5708 0"/>
      <geometry>
        <mesh filename="file://$(find rossy)/description/assets/tire.stl"/>
      </geometry>
      <material name="tire_2_material">
        <color rgba="0.301961 0.301961 0.301961 1"/>
      </material>
    </visual>
    <collision>
      <origin xyz="0 -0 -0.01825" rpy="0 0 0"/>
      <geometry>
        <cylinder radius="0.03" length="0.025"/>
      </geometry>
    </collision>
    <!-- Part hex_nut_2 -->
    <visual>
      <origin xyz="0 -0 -0.018" rpy="1.5708 -0 -0"/>
      <geometry>
        <mesh filename="file://$(find rossy)/description/assets/hex_nut.stl"/>
      </geometry>
      <material name="hex_nut_2_material">
        <color rgba="1 0.870588 0.529412 1"/>
      </material>
    </visual>
    
  </link>
  <!-- Joint from base_link_chassis to wheel_2 -->
  <joint name="right_wheel" type="continuous">
    <origin xyz="-0.0602058 -0.086 0.0085" rpy="-1.5708 -1.5708 0"/>
    <parent link="base_link_chassis"/>
    <child link="wheel_2"/>
    <axis xyz="0 0 1"/>
    <limit effort="10" velocity="10"/>
  </joint>
  <!-- Joint from base_link to base_link_chassis -->
  <joint name="base_link_to_base_link_chassis" type="fixed">
    <origin xyz="0 0 0" rpy="0 -0 0"/>
    <parent link="base_link"/>
    <child link="base_link_chassis"/>
    <axis xyz="0 0 1"/>
    <limit effort="10" velocity="10"/>
  </joint>

  <gazebo reference="base_link">
    <mu1 value="0.001"/> 
    <mu2 value="0.001"/>
  </gazebo>
</robot>

